5:return {{["x"] = 0, ["meta"] = {["fields"] = {}, ["inventory"] = {}}, ["y"] = 0, ["z"] = 0, ["name"] = "default:desert_stonebrick"}, {["x"] = 0, ["meta"] = {["fields"] = {}, ["inventory"] = {}}, ["y"] = 0, ["z"] = 1, ["name"] = "default:desert_stonebrick"}, {["x"] = 0, ["meta"] = {["fields"] = {}, ["inventory"] = {}}, ["y"] = 0, ["z"] = 2, ["name"] = "default:desert_stonebrick"}, {["x"] = 0, ["meta"] = {["fields"] = {}, ["inventory"] = {}}, ["y"] = 0, ["z"] = 3, ["name"] = "default:desert_stonebrick"}, {["x"] = 0, ["meta"] = {["fields"] = {}, ["inventory"] = {}}, ["y"] = 0, ["z"] = 4, ["name"] = "default:desert_stonebrick"}, {["x"] = 0, ["meta"] = {["fields"] = {}, ["inventory"] = {}}, ["y"] = 0, ["z"] = 5, ["name"] = "default:desert_stonebrick"}, {["x"] = 0, ["meta"] = {["fields"] = {}, ["inventory"] = {}}, ["y"] = 0, ["z"] = 6, ["name"] = "default:desert_stonebrick"}, {["x"] = 0, ["meta"] = {["fields"] = {}, ["inventory"] = {}}, ["y"] = 0, ["z"] = 7, ["name"] = "default:desert_stonebrick"}, {["x"] = 0, ["meta"] = {["fields"] = {}, ["inventory"] = {}}, ["y"] = 0, ["z"] = 8, ["name"] = "default:desert_stonebrick"}, {["x"] = 0, ["meta"] = {["fields"] = {}, ["inventory"] = {}}, ["y"] = 0, ["z"] = 9, ["name"] = "default:desert_stonebrick"}, {["x"] = 0, ["meta"] = {["fields"] = {}, ["inventory"] = {}}, ["y"] = 1, ["z"] = 0, ["name"] = "default:stonebrick"}, {["x"] = 0, ["meta"] = {["fields"] = {}, ["inventory"] = {}}, ["y"] = 1, ["z"] = 1, ["name"] = "default:desert_stonebrick"}, {["x"] = 0, ["meta"] = {["fields"] = {}, ["inventory"] = {}}, ["y"] = 1, ["z"] = 2, ["name"] = "default:desert_stonebrick"}, {["x"] = 0, ["meta"] = {["fields"] = {}, ["inventory"] = {}}, ["y"] = 1, ["z"] = 3, ["name"] = "default:desert_stonebrick"}, {["x"] = 0, ["meta"] = {["fields"] = {}, ["inventory"] = {}}, ["y"] = 1, ["z"] = 4, ["name"] = "default:desert_stonebrick"}, {["x"] = 0, ["meta"] = {["fields"] = {}, ["inventory"] = {}}, ["y"] = 1, ["z"] = 5, ["name"] = "default:desert_stonebrick"}, {["x"] = 0, ["meta"] = {["fields"] = {}, ["inventory"] = {}}, ["y"] = 1, ["z"] = 6, ["name"] = "default:desert_stonebrick"}, {["x"] = 0, ["meta"] = {["fields"] = {}, ["inventory"] = {}}, ["y"] = 1, ["z"] = 7, ["name"] = "default:desert_stonebrick"}, {["x"] = 0, ["meta"] = {["fields"] = {}, ["inventory"] = {}}, ["y"] = 1, ["z"] = 8, ["name"] = "default:desert_stonebrick"}, {["x"] = 0, ["meta"] = {["fields"] = {}, ["inventory"] = {}}, ["y"] = 1, ["z"] = 9, ["name"] = "default:desert_stonebrick"}, {["x"] = 0, ["meta"] = {["fields"] = {}, ["inventory"] = {}}, ["y"] = 2, ["z"] = 0, ["name"] = "default:desert_stonebrick"}, {["x"] = 0, ["meta"] = {["fields"] = {}, ["inventory"] = {}}, ["y"] = 2, ["z"] = 1, ["name"] = "default:desert_stonebrick"}, {["x"] = 0, ["meta"] = {["fields"] = {}, ["inventory"] = {}}, ["y"] = 2, ["z"] = 2, ["name"] = "default:desert_stonebrick"}, {["x"] = 0, ["meta"] = {["fields"] = {}, ["inventory"] = {}}, ["y"] = 2, ["z"] = 3, ["name"] = "default:desert_stonebrick"}, {["x"] = 0, ["meta"] = {["fields"] = {}, ["inventory"] = {}}, ["y"] = 2, ["z"] = 4, ["name"] = "default:desert_stonebrick"}, {["x"] = 0, ["meta"] = {["fields"] = {}, ["inventory"] = {}}, ["y"] = 2, ["z"] = 5, ["name"] = "default:desert_stonebrick"}, {["x"] = 0, ["meta"] = {["fields"] = {}, ["inventory"] = {}}, ["y"] = 2, ["z"] = 6, ["name"] = "default:desert_stonebrick"}, {["x"] = 0, ["meta"] = {["fields"] = {}, ["inventory"] = {}}, ["y"] = 2, ["z"] = 7, ["name"] = "default:desert_stonebrick"}, {["x"] = 0, ["meta"] = {["fields"] = {}, ["inventory"] = {}}, ["y"] = 2, ["z"] = 8, ["name"] = "default:desert_stonebrick"}, {["x"] = 0, ["meta"] = {["fields"] = {}, ["inventory"] = {}}, ["y"] = 2, ["z"] = 9, ["name"] = "default:desert_stonebrick"}, {["x"] = 0, ["meta"] = {["fields"] = {}, ["inventory"] = {}}, ["y"] = 3, ["z"] = 0, ["name"] = "default:desert_stonebrick"}, {["x"] = 0, ["meta"] = {["fields"] = {}, ["inventory"] = {}}, ["y"] = 3, ["z"] = 1, ["name"] = "default:desert_stonebrick"}, {["x"] = 0, ["meta"] = {["fields"] = {}, ["inventory"] = {}}, ["y"] = 3, ["z"] = 2, ["name"] = "default:desert_stonebrick"}, {["x"] = 0, ["meta"] = {["fields"] = {}, ["inventory"] = {}}, ["y"] = 3, ["z"] = 3, ["name"] = "default:desert_stonebrick"}, {["x"] = 0, ["meta"] = {["fields"] = {}, ["inventory"] = {}}, ["y"] = 3, ["param1"] = 141, ["z"] = 4, ["name"] = "xpanes:bar_10"}, {["x"] = 0, ["meta"] = {["fields"] = {}, ["inventory"] = {}}, ["y"] = 3, ["param1"] = 141, ["z"] = 5, ["name"] = "xpanes:bar_10"}, {["x"] = 0, ["meta"] = {["fields"] = {}, ["inventory"] = {}}, ["y"] = 3, ["param1"] = 125, ["z"] = 6, ["name"] = "xpanes:bar_10"}, {["x"] = 0, ["meta"] = {["fields"] = {}, ["inventory"] = {}}, ["y"] = 3, ["z"] = 7, ["name"] = "default:desert_stonebrick"}, {["x"] = 0, ["meta"] = {["fields"] = {}, ["inventory"] = {}}, ["y"] = 3, ["z"] = 8, ["name"] = "default:desert_stonebrick"}, {["x"] = 0, ["meta"] = {["fields"] = {}, ["inventory"] = {}}, ["y"] = 3, ["z"] = 9, ["name"] = "default:desert_stonebrick"}, {["x"] = 0, ["meta"] = {["fields"] = {}, ["inventory"] = {}}, ["y"] = 4, ["z"] = 0, ["name"] = "default:desert_stonebrick"}, {["x"] = 0, ["meta"] = {["fields"] = {}, ["inventory"] = {}}, ["y"] = 4, ["z"] = 1, ["name"] = "default:desert_stonebrick"}, {["x"] = 0, ["meta"] = {["fields"] = {}, ["inventory"] = {}}, ["y"] = 4, ["z"] = 2, ["name"] = "default:desert_stonebrick"}, {["x"] = 0, ["meta"] = {["fields"] = {}, ["inventory"] = {}}, ["y"] = 4, ["z"] = 3, ["name"] = "default:desert_stonebrick"}, {["x"] = 0, ["meta"] = {["fields"] = {}, ["inventory"] = {}}, ["y"] = 4, ["z"] = 4, ["name"] = "default:desert_stonebrick"}, {["x"] = 0, ["meta"] = {["fields"] = {}, ["inventory"] = {}}, ["y"] = 4, ["z"] = 5, ["name"] = "default:desert_stonebrick"}, {["x"] = 0, ["meta"] = {["fields"] = {}, ["inventory"] = {}}, ["y"] = 4, ["z"] = 6, ["name"] = "default:desert_stonebrick"}, {["x"] = 0, ["meta"] = {["fields"] = {}, ["inventory"] = {}}, ["y"] = 4, ["z"] = 7, ["name"] = "default:desert_stonebrick"}, {["x"] = 0, ["meta"] = {["fields"] = {}, ["inventory"] = {}}, ["y"] = 4, ["z"] = 8, ["name"] = "default:desert_stonebrick"}, {["x"] = 0, ["meta"] = {["fields"] = {}, ["inventory"] = {}}, ["y"] = 4, ["z"] = 9, ["name"] = "default:desert_stonebrick"}, {["x"] = 0, ["meta"] = {["fields"] = {}, ["inventory"] = {}}, ["y"] = 5, ["z"] = 0, ["name"] = "default:desert_stonebrick"}, {["x"] = 0, ["meta"] = {["fields"] = {}, ["inventory"] = {}}, ["y"] = 5, ["z"] = 1, ["name"] = "default:desert_stonebrick"}, {["x"] = 0, ["meta"] = {["fields"] = {}, ["inventory"] = {}}, ["y"] = 5, ["z"] = 2, ["name"] = "default:desert_stonebrick"}, {["x"] = 0, ["meta"] = {["fields"] = {}, ["inventory"] = {}}, ["y"] = 5, ["z"] = 3, ["name"] = "default:desert_stonebrick"}, {["x"] = 0, ["meta"] = {["fields"] = {}, ["inventory"] = {}}, ["y"] = 5, ["z"] = 4, ["name"] = "default:desert_stonebrick"}, {["x"] = 0, ["meta"] = {["fields"] = {}, ["inventory"] = {}}, ["y"] = 5, ["z"] = 5, ["name"] = "default:desert_stonebrick"}, {["x"] = 0, ["meta"] = {["fields"] = {}, ["inventory"] = {}}, ["y"] = 5, ["z"] = 6, ["name"] = "default:desert_stonebrick"}, {["x"] = 0, ["meta"] = {["fields"] = {}, ["inventory"] = {}}, ["y"] = 5, ["z"] = 7, ["name"] = "default:desert_stonebrick"}, {["x"] = 0, ["meta"] = {["fields"] = {}, ["inventory"] = {}}, ["y"] = 5, ["z"] = 8, ["name"] = "default:desert_stonebrick"}, {["x"] = 0, ["meta"] = {["fields"] = {}, ["inventory"] = {}}, ["y"] = 5, ["z"] = 9, ["name"] = "default:desert_stonebrick"}, {["x"] = 0, ["meta"] = {["fields"] = {}, ["inventory"] = {}}, ["y"] = 6, ["z"] = 0, ["name"] = "default:desert_stonebrick"}, {["x"] = 0, ["meta"] = {["fields"] = {}, ["inventory"] = {}}, ["y"] = 6, ["z"] = 1, ["name"] = "default:desert_stonebrick"}, {["x"] = 0, ["meta"] = {["fields"] = {}, ["inventory"] = {}}, ["y"] = 6, ["z"] = 2, ["name"] = "default:desert_stonebrick"}, {["x"] = 0, ["meta"] = {["fields"] = {}, ["inventory"] = {}}, ["y"] = 6, ["z"] = 3, ["name"] = "default:desert_stonebrick"}, {["x"] = 0, ["meta"] = {["fields"] = {}, ["inventory"] = {}}, ["y"] = 6, ["z"] = 4, ["name"] = "default:desert_stonebrick"}, {["x"] = 0, ["meta"] = {["fields"] = {}, ["inventory"] = {}}, ["y"] = 6, ["z"] = 5, ["name"] = "default:desert_stonebrick"}, {["x"] = 0, ["meta"] = {["fields"] = {}, ["inventory"] = {}}, ["y"] = 6, ["z"] = 6, ["name"] = "default:desert_stonebrick"}, {["x"] = 0, ["meta"] = {["fields"] = {}, ["inventory"] = {}}, ["y"] = 6, ["z"] = 7, ["name"] = "default:desert_stonebrick"}, {["x"] = 0, ["meta"] = {["fields"] = {}, ["inventory"] = {}}, ["y"] = 6, ["z"] = 8, ["name"] = "default:desert_stonebrick"}, {["x"] = 0, ["meta"] = {["fields"] = {}, ["inventory"] = {}}, ["y"] = 6, ["z"] = 9, ["name"] = "default:desert_stonebrick"}, {["x"] = 0, ["meta"] = {["fields"] = {}, ["inventory"] = {}}, ["y"] = 7, ["z"] = 0, ["name"] = "default:desert_stonebrick"}, {["x"] = 0, ["meta"] = {["fields"] = {}, ["inventory"] = {}}, ["y"] = 7, ["z"] = 1, ["name"] = "default:desert_stonebrick"}, {["x"] = 0, ["meta"] = {["fields"] = {}, ["inventory"] = {}}, ["y"] = 7, ["z"] = 2, ["name"] = "default:desert_stonebrick"}, {["x"] = 0, ["meta"] = {["fields"] = {}, ["inventory"] = {}}, ["y"] = 7, ["z"] = 3, ["name"] = "default:desert_stonebrick"}, {["x"] = 0, ["meta"] = {["fields"] = {}, ["inventory"] = {}}, ["y"] = 7, ["z"] = 4, ["name"] = "default:desert_stonebrick"}, {["x"] = 0, ["meta"] = {["fields"] = {}, ["inventory"] = {}}, ["y"] = 7, ["z"] = 5, ["name"] = "default:desert_stonebrick"}, {["x"] = 0, ["meta"] = {["fields"] = {}, ["inventory"] = {}}, ["y"] = 7, ["z"] = 6, ["name"] = "default:desert_stonebrick"}, {["x"] = 0, ["meta"] = {["fields"] = {}, ["inventory"] = {}}, ["y"] = 7, ["z"] = 7, ["name"] = "default:desert_stonebrick"}, {["x"] = 0, ["meta"] = {["fields"] = {}, ["inventory"] = {}}, ["y"] = 7, ["z"] = 8, ["name"] = "default:desert_stonebrick"}, {["x"] = 0, ["meta"] = {["fields"] = {}, ["inventory"] = {}}, ["y"] = 7, ["z"] = 9, ["name"] = "default:desert_stonebrick"}, {["x"] = 0, ["meta"] = {["fields"] = {}, ["inventory"] = {}}, ["y"] = 8, ["z"] = 0, ["name"] = "default:desert_stonebrick"}, {["x"] = 0, ["meta"] = {["fields"] = {}, ["inventory"] = {}}, ["y"] = 8, ["z"] = 1, ["name"] = "default:desert_stonebrick"}, {["x"] = 0, ["meta"] = {["fields"] = {}, ["inventory"] = {}}, ["y"] = 8, ["z"] = 2, ["name"] = "default:desert_stonebrick"}, {["x"] = 0, ["meta"] = {["fields"] = {}, ["inventory"] = {}}, ["y"] = 8, ["z"] = 3, ["name"] = "default:desert_stonebrick"}, {["x"] = 0, ["meta"] = {["fields"] = {}, ["inventory"] = {}}, ["y"] = 8, ["z"] = 4, ["name"] = "default:desert_stonebrick"}, {["x"] = 0, ["meta"] = {["fields"] = {}, ["inventory"] = {}}, ["y"] = 8, ["z"] = 5, ["name"] = "default:desert_stonebrick"}, {["x"] = 0, ["meta"] = {["fields"] = {}, ["inventory"] = {}}, ["y"] = 8, ["z"] = 6, ["name"] = "default:desert_stonebrick"}, {["x"] = 0, ["meta"] = {["fields"] = {}, ["inventory"] = {}}, ["y"] = 8, ["z"] = 7, ["name"] = "default:desert_stonebrick"}, {["x"] = 0, ["meta"] = {["fields"] = {}, ["inventory"] = {}}, ["y"] = 8, ["z"] = 8, ["name"] = "default:desert_stonebrick"}, {["x"] = 0, ["meta"] = {["fields"] = {}, ["inventory"] = {}}, ["y"] = 8, ["z"] = 9, ["name"] = "default:desert_stonebrick"}, {["x"] = 1, ["meta"] = {["fields"] = {}, ["inventory"] = {}}, ["y"] = 0, ["z"] = 0, ["name"] = "default:desert_stonebrick"}, {["x"] = 1, ["meta"] = {["fields"] = {}, ["inventory"] = {}}, ["y"] = 0, ["z"] = 1, ["name"] = "default:desert_stonebrick"}, {["x"] = 1, ["meta"] = {["fields"] = {}, ["inventory"] = {}}, ["y"] = 0, ["z"] = 2, ["name"] = "default:desert_stonebrick"}, {["x"] = 1, ["meta"] = {["fields"] = {}, ["inventory"] = {}}, ["y"] = 0, ["z"] = 3, ["name"] = "default:desert_stonebrick"}, {["x"] = 1, ["meta"] = {["fields"] = {}, ["inventory"] = {}}, ["y"] = 0, ["z"] = 4, ["name"] = "default:desert_stonebrick"}, {["x"] = 1, ["meta"] = {["fields"] = {}, ["inventory"] = {}}, ["y"] = 0, ["z"] = 5, ["name"] = "default:desert_stonebrick"}, {["x"] = 1, ["meta"] = {["fields"] = {}, ["inventory"] = {}}, ["y"] = 0, ["z"] = 6, ["name"] = "default:desert_stonebrick"}, {["x"] = 1, ["meta"] = {["fields"] = {}, ["inventory"] = {}}, ["y"] = 0, ["z"] = 7, ["name"] = "default:desert_stonebrick"}, {["x"] = 1, ["meta"] = {["fields"] = {}, ["inventory"] = {}}, ["y"] = 0, ["z"] = 8, ["name"] = "default:desert_stonebrick"}, {["x"] = 1, ["meta"] = {["fields"] = {}, ["inventory"] = {}}, ["y"] = 0, ["z"] = 9, ["name"] = "default:desert_stonebrick"}, {["x"] = 1, ["meta"] = {["fields"] = {}, ["inventory"] = {}}, ["y"] = 1, ["z"] = 0, ["name"] = "default:stonebrick"}, {["x"] = 1, ["meta"] = {["fields"] = {}, ["inventory"] = {}}, ["y"] = 1, ["z"] = 1, ["name"] = "default:stonebrick"}, {["x"] = 1, ["meta"] = {["fields"] = {}, ["inventory"] = {}}, ["y"] = 1, ["z"] = 2, ["name"] = "default:stonebrick"}, {["x"] = 1, ["meta"] = {["fields"] = {}, ["inventory"] = {}}, ["y"] = 1, ["z"] = 3, ["name"] = "default:stonebrick"}, {["x"] = 1, ["meta"] = {["fields"] = {}, ["inventory"] = {}}, ["y"] = 1, ["z"] = 4, ["name"] = "default:stonebrick"}, {["x"] = 1, ["meta"] = {["fields"] = {}, ["inventory"] = {}}, ["y"] = 1, ["z"] = 5, ["name"] = "default:stonebrick"}, {["x"] = 1, ["meta"] = {["fields"] = {}, ["inventory"] = {}}, ["y"] = 1, ["z"] = 6, ["name"] = "default:stonebrick"}, {["x"] = 1, ["meta"] = {["fields"] = {}, ["inventory"] = {}}, ["y"] = 1, ["z"] = 7, ["name"] = "default:stonebrick"}, {["x"] = 1, ["meta"] = {["fields"] = {}, ["inventory"] = {}}, ["y"] = 1, ["z"] = 8, ["name"] = "default:stonebrick"}, {["x"] = 1, ["meta"] = {["fields"] = {}, ["inventory"] = {}}, ["y"] = 1, ["z"] = 9, ["name"] = "default:desert_stonebrick"}, {["x"] = 1, ["meta"] = {["fields"] = {}, ["inventory"] = {}}, ["y"] = 2, ["z"] = 0, ["name"] = "default:desert_stonebrick"}, {["x"] = 1, ["meta"] = {["fields"] = {}, ["inventory"] = {}}, ["y"] = 2, ["z"] = 9, ["name"] = "default:desert_stonebrick"}, {["x"] = 1, ["meta"] = {["fields"] = {}, ["inventory"] = {}}, ["y"] = 3, ["z"] = 0, ["name"] = "default:desert_stonebrick"}, {["x"] = 1, ["meta"] = {["fields"] = {}, ["inventory"] = {}}, ["y"] = 3, ["z"] = 9, ["name"] = "default:desert_stonebrick"}, {["x"] = 1, ["meta"] = {["fields"] = {}, ["inventory"] = {}}, ["y"] = 4, ["z"] = 0, ["name"] = "default:desert_stonebrick"}, {["x"] = 1, ["meta"] = {["fields"] = {}, ["inventory"] = {}}, ["y"] = 4, ["z"] = 9, ["name"] = "default:desert_stonebrick"}, {["x"] = 1, ["meta"] = {["fields"] = {}, ["inventory"] = {}}, ["y"] = 5, ["z"] = 0, ["name"] = "default:desert_stonebrick"}, {["x"] = 1, ["meta"] = {["fields"] = {}, ["inventory"] = {}}, ["y"] = 5, ["z"] = 9, ["name"] = "default:desert_stonebrick"}, {["x"] = 1, ["meta"] = {["fields"] = {}, ["inventory"] = {}}, ["y"] = 6, ["param1"] = 111, ["z"] = 0, ["name"] = "default:desert_stonebrick"}, {["x"] = 1, ["meta"] = {["fields"] = {}, ["inventory"] = {}}, ["y"] = 6, ["z"] = 9, ["name"] = "default:desert_stonebrick"}, {["x"] = 1, ["meta"] = {["fields"] = {}, ["inventory"] = {}}, ["y"] = 7, ["z"] = 0, ["name"] = "default:stonebrick"}, {["x"] = 1, ["meta"] = {["fields"] = {}, ["inventory"] = {}}, ["y"] = 7, ["z"] = 1, ["name"] = "default:stonebrick"}, {["x"] = 1, ["meta"] = {["fields"] = {}, ["inventory"] = {}}, ["y"] = 7, ["z"] = 2, ["name"] = "default:stonebrick"}, {["x"] = 1, ["meta"] = {["fields"] = {}, ["inventory"] = {}}, ["y"] = 7, ["z"] = 3, ["name"] = "default:stonebrick"}, {["x"] = 1, ["meta"] = {["fields"] = {}, ["inventory"] = {}}, ["y"] = 7, ["z"] = 4, ["name"] = "default:stonebrick"}, {["x"] = 1, ["meta"] = {["fields"] = {}, ["inventory"] = {}}, ["y"] = 7, ["z"] = 5, ["name"] = "default:stonebrick"}, {["x"] = 1, ["meta"] = {["fields"] = {}, ["inventory"] = {}}, ["y"] = 7, ["z"] = 6, ["name"] = "default:stonebrick"}, {["x"] = 1, ["meta"] = {["fields"] = {}, ["inventory"] = {}}, ["y"] = 7, ["z"] = 7, ["name"] = "default:stonebrick"}, {["x"] = 1, ["meta"] = {["fields"] = {}, ["inventory"] = {}}, ["y"] = 7, ["z"] = 8, ["name"] = "default:stonebrick"}, {["x"] = 1, ["meta"] = {["fields"] = {}, ["inventory"] = {}}, ["y"] = 7, ["z"] = 9, ["name"] = "default:desert_stonebrick"}, {["x"] = 1, ["meta"] = {["fields"] = {}, ["inventory"] = {}}, ["y"] = 8, ["param1"] = 79, ["z"] = 0, ["name"] = "default:desert_stonebrick"}, {["x"] = 1, ["meta"] = {["fields"] = {}, ["inventory"] = {}}, ["y"] = 8, ["z"] = 1, ["name"] = "default:desert_stonebrick"}, {["x"] = 1, ["meta"] = {["fields"] = {}, ["inventory"] = {}}, ["y"] = 8, ["z"] = 2, ["name"] = "default:desert_stonebrick"}, {["x"] = 1, ["meta"] = {["fields"] = {}, ["inventory"] = {}}, ["y"] = 8, ["z"] = 3, ["name"] = "default:desert_stonebrick"}, {["x"] = 1, ["meta"] = {["fields"] = {}, ["inventory"] = {}}, ["y"] = 8, ["z"] = 4, ["name"] = "default:desert_stonebrick"}, {["x"] = 1, ["meta"] = {["fields"] = {}, ["inventory"] = {}}, ["y"] = 8, ["z"] = 5, ["name"] = "default:desert_stonebrick"}, {["x"] = 1, ["meta"] = {["fields"] = {}, ["inventory"] = {}}, ["y"] = 8, ["z"] = 6, ["name"] = "default:desert_stonebrick"}, {["x"] = 1, ["meta"] = {["fields"] = {}, ["inventory"] = {}}, ["y"] = 8, ["z"] = 7, ["name"] = "default:desert_stonebrick"}, {["x"] = 1, ["meta"] = {["fields"] = {}, ["inventory"] = {}}, ["y"] = 8, ["z"] = 8, ["name"] = "default:desert_stonebrick"}, {["x"] = 1, ["meta"] = {["fields"] = {}, ["inventory"] = {}}, ["y"] = 8, ["z"] = 9, ["name"] = "default:desert_stonebrick"}, {["x"] = 2, ["meta"] = {["fields"] = {}, ["inventory"] = {}}, ["y"] = 0, ["z"] = 0, ["name"] = "default:desert_stonebrick"}, {["x"] = 2, ["meta"] = {["fields"] = {}, ["inventory"] = {}}, ["y"] = 0, ["z"] = 1, ["name"] = "default:desert_stonebrick"}, {["x"] = 2, ["meta"] = {["fields"] = {}, ["inventory"] = {}}, ["y"] = 0, ["z"] = 2, ["name"] = "default:desert_stonebrick"}, {["x"] = 2, ["meta"] = {["fields"] = {}, ["inventory"] = {}}, ["y"] = 0, ["z"] = 3, ["name"] = "default:desert_stonebrick"}, {["x"] = 2, ["meta"] = {["fields"] = {}, ["inventory"] = {}}, ["y"] = 0, ["z"] = 4, ["name"] = "default:desert_stonebrick"}, {["x"] = 2, ["meta"] = {["fields"] = {}, ["inventory"] = {}}, ["y"] = 0, ["z"] = 5, ["name"] = "default:desert_stonebrick"}, {["x"] = 2, ["meta"] = {["fields"] = {}, ["inventory"] = {}}, ["y"] = 0, ["z"] = 6, ["name"] = "default:desert_stonebrick"}, {["x"] = 2, ["meta"] = {["fields"] = {}, ["inventory"] = {}}, ["y"] = 0, ["z"] = 7, ["name"] = "default:desert_stonebrick"}, {["x"] = 2, ["meta"] = {["fields"] = {}, ["inventory"] = {}}, ["y"] = 0, ["z"] = 8, ["name"] = "default:desert_stonebrick"}, {["x"] = 2, ["meta"] = {["fields"] = {}, ["inventory"] = {}}, ["y"] = 0, ["z"] = 9, ["name"] = "default:desert_stonebrick"}, {["x"] = 2, ["meta"] = {["fields"] = {}, ["inventory"] = {}}, ["y"] = 1, ["z"] = 0, ["name"] = "default:stonebrick"}, {["x"] = 2, ["meta"] = {["fields"] = {}, ["inventory"] = {}}, ["y"] = 1, ["z"] = 1, ["name"] = "default:stonebrick"}, {["x"] = 2, ["meta"] = {["fields"] = {}, ["inventory"] = {}}, ["y"] = 1, ["z"] = 8, ["name"] = "default:stonebrick"}, {["x"] = 2, ["meta"] = {["fields"] = {}, ["inventory"] = {}}, ["y"] = 1, ["z"] = 9, ["name"] = "default:desert_stonebrick"}, {["x"] = 2, ["meta"] = {["fields"] = {}, ["inventory"] = {}}, ["y"] = 2, ["z"] = 0, ["name"] = "default:desert_stonebrick"}, {["x"] = 2, ["meta"] = {["fields"] = {}, ["inventory"] = {}}, ["y"] = 2, ["z"] = 9, ["name"] = "default:desert_stonebrick"}, {["x"] = 2, ["meta"] = {["fields"] = {}, ["inventory"] = {}}, ["y"] = 3, ["z"] = 0, ["name"] = "default:stonebrick"}, {["x"] = 2, ["meta"] = {["fields"] = {}, ["inventory"] = {}}, ["y"] = 3, ["z"] = 9, ["name"] = "default:desert_stonebrick"}, {["x"] = 2, ["meta"] = {["fields"] = {}, ["inventory"] = {}}, ["y"] = 4, ["z"] = 0, ["name"] = "default:stonebrick"}, {["x"] = 2, ["meta"] = {["fields"] = {}, ["inventory"] = {}}, ["y"] = 4, ["z"] = 9, ["name"] = "default:desert_stonebrick"}, {["x"] = 2, ["meta"] = {["fields"] = {}, ["inventory"] = {}}, ["y"] = 5, ["z"] = 0, ["name"] = "default:stonebrick"}, {["x"] = 2, ["meta"] = {["fields"] = {}, ["inventory"] = {}}, ["y"] = 5, ["z"] = 9, ["name"] = "default:desert_stonebrick"}, {["x"] = 2, ["meta"] = {["fields"] = {}, ["inventory"] = {}}, ["y"] = 6, ["param1"] = 127, ["z"] = 0, ["name"] = "default:desert_stonebrick"}, {["x"] = 2, ["meta"] = {["fields"] = {}, ["inventory"] = {}}, ["y"] = 6, ["z"] = 9, ["name"] = "default:desert_stonebrick"}, {["x"] = 2, ["meta"] = {["fields"] = {}, ["inventory"] = {}}, ["y"] = 7, ["z"] = 0, ["name"] = "default:stonebrick"}, {["x"] = 2, ["meta"] = {["fields"] = {}, ["inventory"] = {}}, ["param2"] = 23, ["y"] = 7, ["param1"] = 120, ["z"] = 1, ["name"] = "stairs:slab_stonebrick"}, {["x"] = 2, ["meta"] = {["fields"] = {}, ["inventory"] = {}}, ["param2"] = 23, ["y"] = 7, ["param1"] = 136, ["z"] = 2, ["name"] = "stairs:slab_stonebrick"}, {["x"] = 2, ["meta"] = {["fields"] = {}, ["inventory"] = {}}, ["param2"] = 23, ["y"] = 7, ["param1"] = 153, ["z"] = 3, ["name"] = "stairs:slab_stonebrick"}, {["x"] = 2, ["meta"] = {["fields"] = {}, ["inventory"] = {}}, ["param2"] = 23, ["y"] = 7, ["param1"] = 170, ["z"] = 4, ["name"] = "stairs:slab_stonebrick"}, {["x"] = 2, ["meta"] = {["fields"] = {}, ["inventory"] = {}}, ["param2"] = 23, ["y"] = 7, ["param1"] = 170, ["z"] = 5, ["name"] = "stairs:slab_stonebrick"}, {["x"] = 2, ["meta"] = {["fields"] = {}, ["inventory"] = {}}, ["param2"] = 23, ["y"] = 7, ["param1"] = 153, ["z"] = 6, ["name"] = "stairs:slab_stonebrick"}, {["x"] = 2, ["meta"] = {["fields"] = {}, ["inventory"] = {}}, ["param2"] = 23, ["y"] = 7, ["param1"] = 136, ["z"] = 7, ["name"] = "stairs:slab_stonebrick"}, {["x"] = 2, ["meta"] = {["fields"] = {}, ["inventory"] = {}}, ["y"] = 7, ["z"] = 8, ["name"] = "default:stonebrick"}, {["x"] = 2, ["meta"] = {["fields"] = {}, ["inventory"] = {}}, ["y"] = 7, ["z"] = 9, ["name"] = "default:desert_stonebrick"}, {["x"] = 2, ["meta"] = {["fields"] = {}, ["inventory"] = {}}, ["y"] = 8, ["param1"] = 95, ["z"] = 0, ["name"] = "default:desert_stonebrick"}, {["x"] = 2, ["meta"] = {["fields"] = {}, ["inventory"] = {}}, ["y"] = 8, ["z"] = 1, ["name"] = "default:desert_stonebrick"}, {["x"] = 2, ["meta"] = {["fields"] = {}, ["inventory"] = {}}, ["y"] = 8, ["z"] = 2, ["name"] = "default:desert_stonebrick"}, {["x"] = 2, ["meta"] = {["fields"] = {}, ["inventory"] = {}}, ["y"] = 8, ["z"] = 3, ["name"] = "default:desert_stonebrick"}, {["x"] = 2, ["meta"] = {["fields"] = {}, ["inventory"] = {}}, ["y"] = 8, ["z"] = 4, ["name"] = "default:desert_stonebrick"}, {["x"] = 2, ["meta"] = {["fields"] = {}, ["inventory"] = {}}, ["y"] = 8, ["z"] = 5, ["name"] = "default:desert_stonebrick"}, {["x"] = 2, ["meta"] = {["fields"] = {}, ["inventory"] = {}}, ["y"] = 8, ["z"] = 6, ["name"] = "default:desert_stonebrick"}, {["x"] = 2, ["meta"] = {["fields"] = {}, ["inventory"] = {}}, ["y"] = 8, ["z"] = 7, ["name"] = "default:desert_stonebrick"}, {["x"] = 2, ["meta"] = {["fields"] = {}, ["inventory"] = {}}, ["y"] = 8, ["z"] = 8, ["name"] = "default:desert_stonebrick"}, {["x"] = 2, ["meta"] = {["fields"] = {}, ["inventory"] = {}}, ["y"] = 8, ["z"] = 9, ["name"] = "default:desert_stonebrick"}, {["x"] = 3, ["meta"] = {["fields"] = {}, ["inventory"] = {}}, ["y"] = 0, ["z"] = 0, ["name"] = "default:desert_stonebrick"}, {["x"] = 3, ["meta"] = {["fields"] = {}, ["inventory"] = {}}, ["y"] = 0, ["z"] = 1, ["name"] = "default:desert_stonebrick"}, {["x"] = 3, ["meta"] = {["fields"] = {}, ["inventory"] = {}}, ["y"] = 0, ["z"] = 2, ["name"] = "default:desert_stonebrick"}, {["x"] = 3, ["meta"] = {["fields"] = {}, ["inventory"] = {}}, ["y"] = 0, ["z"] = 3, ["name"] = "default:stonebrick"}, {["x"] = 3, ["meta"] = {["fields"] = {}, ["inventory"] = {}}, ["y"] = 0, ["param1"] = 141, ["z"] = 4, ["name"] = "default:glass"}, {["x"] = 3, ["meta"] = {["fields"] = {}, ["inventory"] = {}}, ["y"] = 0, ["z"] = 5, ["name"] = "default:stonebrick"}, {["x"] = 3, ["meta"] = {["fields"] = {}, ["inventory"] = {}}, ["y"] = 0, ["z"] = 6, ["name"] = "default:desert_stonebrick"}, {["x"] = 3, ["meta"] = {["fields"] = {}, ["inventory"] = {}}, ["y"] = 0, ["z"] = 7, ["name"] = "default:desert_stonebrick"}, {["x"] = 3, ["meta"] = {["fields"] = {}, ["inventory"] = {}}, ["y"] = 0, ["z"] = 8, ["name"] = "default:desert_stonebrick"}, {["x"] = 3, ["meta"] = {["fields"] = {}, ["inventory"] = {}}, ["y"] = 0, ["z"] = 9, ["name"] = "default:desert_stonebrick"}, {["x"] = 3, ["meta"] = {["fields"] = {}, ["inventory"] = {}}, ["y"] = 1, ["z"] = 0, ["name"] = "default:stonebrick"}, {["x"] = 3, ["meta"] = {["fields"] = {}, ["inventory"] = {}}, ["y"] = 1, ["z"] = 1, ["name"] = "default:stonebrick"}, {["x"] = 3, ["meta"] = {["fields"] = {}, ["inventory"] = {}}, ["y"] = 1, ["param1"] = 187, ["z"] = 7, ["name"] = "stairs:slab_stonebrick"}, {["x"] = 3, ["meta"] = {["fields"] = {}, ["inventory"] = {}}, ["y"] = 1, ["z"] = 8, ["name"] = "default:stonebrick"}, {["x"] = 3, ["meta"] = {["fields"] = {}, ["inventory"] = {}}, ["y"] = 1, ["z"] = 9, ["name"] = "default:desert_stonebrick"}, {["x"] = 3, ["meta"] = {["fields"] = {}, ["inventory"] = {}}, ["y"] = 2, ["z"] = 0, ["name"] = "default:stonebrick"}, {["x"] = 3, ["meta"] = {["fields"] = {}, ["inventory"] = {}}, ["param2"] = 1, ["y"] = 2, ["z"] = 8, ["name"] = "default:torch"}, {["x"] = 3, ["meta"] = {["fields"] = {}, ["inventory"] = {}}, ["y"] = 2, ["z"] = 9, ["name"] = "default:desert_stonebrick"}, {["x"] = 3, ["meta"] = {["fields"] = {}, ["inventory"] = {}}, ["y"] = 3, ["z"] = 0, ["name"] = "default:stonebrick"}, {["x"] = 3, ["meta"] = {["fields"] = {}, ["inventory"] = {}}, ["y"] = 3, ["param1"] = 189, ["z"] = 9, ["name"] = "xpanes:bar_5"}, {["x"] = 3, ["meta"] = {["fields"] = {}, ["inventory"] = {}}, ["y"] = 4, ["param1"] = 141, ["z"] = 0, ["name"] = "xpanes:bar_5"}, {["x"] = 3, ["meta"] = {["fields"] = {}, ["inventory"] = {}}, ["y"] = 4, ["param1"] = 204, ["z"] = 4, ["name"] = "default:fence_wood"}, {["x"] = 3, ["meta"] = {["fields"] = {}, ["inventory"] = {}}, ["y"] = 4, ["param1"] = 204, ["z"] = 5, ["name"] = "default:fence_wood"}, {["x"] = 3, ["meta"] = {["fields"] = {}, ["inventory"] = {}}, ["y"] = 4, ["param1"] = 187, ["z"] = 6, ["name"] = "default:fence_wood"}, {["x"] = 3, ["meta"] = {["fields"] = {}, ["inventory"] = {}}, ["y"] = 4, ["z"] = 9, ["name"] = "default:desert_stonebrick"}, {["x"] = 3, ["meta"] = {["fields"] = {}, ["inventory"] = {}}, ["y"] = 5, ["z"] = 0, ["name"] = "default:stonebrick"}, {["x"] = 3, ["meta"] = {["fields"] = {}, ["inventory"] = {}}, ["param2"] = 1, ["y"] = 5, ["z"] = 4, ["name"] = "default:torch"}, {["x"] = 3, ["meta"] = {["fields"] = {}, ["inventory"] = {}}, ["param2"] = 1, ["y"] = 5, ["z"] = 5, ["name"] = "default:torch"}, {["x"] = 3, ["meta"] = {["fields"] = {}, ["inventory"] = {}}, ["y"] = 5, ["z"] = 9, ["name"] = "default:desert_stonebrick"}, {["x"] = 3, ["meta"] = {["fields"] = {}, ["inventory"] = {}}, ["y"] = 6, ["param1"] = 143, ["z"] = 0, ["name"] = "default:desert_stonebrick"}, {["x"] = 3, ["meta"] = {["fields"] = {}, ["inventory"] = {}}, ["y"] = 6, ["z"] = 9, ["name"] = "default:desert_stonebrick"}, {["x"] = 3, ["meta"] = {["fields"] = {}, ["inventory"] = {}}, ["y"] = 7, ["z"] = 0, ["name"] = "default:stonebrick"}, {["x"] = 3, ["meta"] = {["fields"] = {}, ["inventory"] = {}}, ["param2"] = 23, ["y"] = 7, ["param1"] = 187, ["z"] = 5, ["name"] = "stairs:stair_desert_stonebrick"}, {["x"] = 3, ["meta"] = {["fields"] = {}, ["inventory"] = {}}, ["param2"] = 23, ["y"] = 7, ["param1"] = 153, ["z"] = 7, ["name"] = "stairs:slab_stonebrick"}, {["x"] = 3, ["meta"] = {["fields"] = {}, ["inventory"] = {}}, ["y"] = 7, ["z"] = 8, ["name"] = "default:stonebrick"}, {["x"] = 3, ["meta"] = {["fields"] = {}, ["inventory"] = {}}, ["y"] = 7, ["z"] = 9, ["name"] = "default:desert_stonebrick"}, {["x"] = 3, ["meta"] = {["fields"] = {}, ["inventory"] = {}}, ["y"] = 8, ["param1"] = 111, ["z"] = 0, ["name"] = "default:desert_stonebrick"}, {["x"] = 3, ["meta"] = {["fields"] = {}, ["inventory"] = {}}, ["y"] = 8, ["z"] = 1, ["name"] = "default:desert_stonebrick"}, {["x"] = 3, ["meta"] = {["fields"] = {}, ["inventory"] = {}}, ["y"] = 8, ["z"] = 2, ["name"] = "default:desert_stonebrick"}, {["x"] = 3, ["meta"] = {["fields"] = {}, ["inventory"] = {}}, ["y"] = 8, ["z"] = 3, ["name"] = "default:desert_stonebrick"}, {["x"] = 3, ["meta"] = {["fields"] = {}, ["inventory"] = {}}, ["y"] = 8, ["z"] = 4, ["name"] = "default:desert_stonebrick"}, {["x"] = 3, ["meta"] = {["fields"] = {}, ["inventory"] = {}}, ["y"] = 8, ["z"] = 5, ["name"] = "default:desert_stonebrick"}, {["x"] = 3, ["meta"] = {["fields"] = {}, ["inventory"] = {}}, ["y"] = 8, ["z"] = 6, ["name"] = "default:desert_stonebrick"}, {["x"] = 3, ["meta"] = {["fields"] = {}, ["inventory"] = {}}, ["y"] = 8, ["z"] = 7, ["name"] = "default:desert_stonebrick"}, {["x"] = 3, ["meta"] = {["fields"] = {}, ["inventory"] = {}}, ["y"] = 8, ["z"] = 8, ["name"] = "default:desert_stonebrick"}, {["x"] = 3, ["meta"] = {["fields"] = {}, ["inventory"] = {}}, ["y"] = 8, ["z"] = 9, ["name"] = "default:desert_stonebrick"}, {["x"] = 4, ["meta"] = {["fields"] = {}, ["inventory"] = {}}, ["y"] = 0, ["z"] = 0, ["name"] = "default:desert_stonebrick"}, {["x"] = 4, ["meta"] = {["fields"] = {}, ["inventory"] = {}}, ["y"] = 0, ["z"] = 1, ["name"] = "default:desert_stonebrick"}, {["x"] = 4, ["meta"] = {["fields"] = {}, ["inventory"] = {}}, ["y"] = 0, ["z"] = 2, ["name"] = "default:desert_stonebrick"}, {["x"] = 4, ["meta"] = {["fields"] = {}, ["inventory"] = {}}, ["y"] = 0, ["param1"] = 125, ["z"] = 3, ["name"] = "default:glass"}, {["x"] = 4, ["meta"] = {["fields"] = {}, ["inventory"] = {}}, ["y"] = 0, ["param1"] = 141, ["z"] = 4, ["name"] = "default:glass"}, {["x"] = 4, ["meta"] = {["fields"] = {}, ["inventory"] = {}}, ["y"] = 0, ["param1"] = 125, ["z"] = 5, ["name"] = "default:glass"}, {["x"] = 4, ["meta"] = {["fields"] = {}, ["inventory"] = {}}, ["y"] = 0, ["z"] = 6, ["name"] = "default:desert_stonebrick"}, {["x"] = 4, ["meta"] = {["fields"] = {}, ["inventory"] = {}}, ["y"] = 0, ["z"] = 7, ["name"] = "default:desert_stonebrick"}, {["x"] = 4, ["meta"] = {["fields"] = {}, ["inventory"] = {}}, ["y"] = 0, ["z"] = 8, ["name"] = "default:desert_stonebrick"}, {["x"] = 4, ["meta"] = {["fields"] = {}, ["inventory"] = {}}, ["y"] = 0, ["z"] = 9, ["name"] = "default:desert_stonebrick"}, {["x"] = 4, ["meta"] = {["fields"] = {}, ["inventory"] = {}}, ["param2"] = 1, ["y"] = 1, ["param1"] = 108, ["z"] = 1, ["name"] = "doors:door_wood_b_2"}, {["x"] = 4, ["meta"] = {["fields"] = {["infotext"] = "Chest", ["formspec"] = "size[8,9]bgcolor[#080808BB;true]background[5,5;1,1;gui_formbg.png;true]listcolors[#00000069;#5A5A5A;#141318;#30434C;#FFF]list[current_name;main;0,0.3;8,4;]list[current_player;main;0,4.85;8,1;]list[current_player;main;0,6.08;8,3;8]listring[current_name;main]listring[current_player;main]image[0,4.85;1,1;gui_hb_bg.png]image[1,4.85;1,1;gui_hb_bg.png]image[2,4.85;1,1;gui_hb_bg.png]image[3,4.85;1,1;gui_hb_bg.png]image[4,4.85;1,1;gui_hb_bg.png]image[5,4.85;1,1;gui_hb_bg.png]image[6,4.85;1,1;gui_hb_bg.png]image[7,4.85;1,1;gui_hb_bg.png]"}, ["inventory"] = {["main"] = {"", "", "", "", "", "", "", "", "", "", "", "", "", "", "", "", "", "", "", "", "", "", "", "", "", "", "", "", "", "", "", ""}}}, ["y"] = 1, ["z"] = 7, ["name"] = "default:chest"}, {["x"] = 4, ["meta"] = {["fields"] = {}, ["inventory"] = {}}, ["y"] = 1, ["z"] = 8, ["name"] = "default:stonebrick"}, {["x"] = 4, ["meta"] = {["fields"] = {}, ["inventory"] = {}}, ["y"] = 1, ["z"] = 9, ["name"] = "default:desert_stonebrick"}, {["x"] = 4, ["meta"] = {["fields"] = {}, ["inventory"] = {}}, ["param2"] = 1, ["y"] = 2, ["param1"] = 124, ["z"] = 1, ["name"] = "doors:door_wood_t_2"}, {["x"] = 4, ["meta"] = {["fields"] = {}, ["inventory"] = {}}, ["y"] = 2, ["param1"] = 204, ["z"] = 8, ["name"] = "stairs:slab_stonebrick"}, {["x"] = 4, ["meta"] = {["fields"] = {}, ["inventory"] = {}}, ["y"] = 2, ["z"] = 9, ["name"] = "default:desert_stonebrick"}, {["x"] = 4, ["meta"] = {["fields"] = {}, ["inventory"] = {}}, ["y"] = 3, ["z"] = 0, ["name"] = "default:stonebrick"}, {["x"] = 4, ["meta"] = {["fields"] = {}, ["inventory"] = {}}, ["y"] = 3, ["param1"] = 173, ["z"] = 9, ["name"] = "xpanes:bar_5"}, {["x"] = 4, ["meta"] = {["fields"] = {}, ["inventory"] = {}}, ["y"] = 4, ["param1"] = 141, ["z"] = 0, ["name"] = "xpanes:bar_5"}, {["x"] = 4, ["meta"] = {["fields"] = {}, ["inventory"] = {}}, ["y"] = 4, ["param1"] = 204, ["z"] = 4, ["name"] = "default:fence_wood"}, {["x"] = 4, ["meta"] = {["fields"] = {}, ["inventory"] = {}}, ["y"] = 4, ["z"] = 5, ["name"] = "wool:grey"}, {["x"] = 4, ["meta"] = {["fields"] = {}, ["inventory"] = {}}, ["y"] = 4, ["param1"] = 204, ["z"] = 6, ["name"] = "default:fence_wood"}, {["x"] = 4, ["meta"] = {["fields"] = {}, ["inventory"] = {}}, ["y"] = 4, ["z"] = 9, ["name"] = "default:desert_stonebrick"}, {["x"] = 4, ["meta"] = {["fields"] = {}, ["inventory"] = {}}, ["y"] = 5, ["z"] = 0, ["name"] = "default:stonebrick"}, {["x"] = 4, ["meta"] = {["fields"] = {}, ["inventory"] = {}}, ["param2"] = 1, ["y"] = 5, ["z"] = 4, ["name"] = "default:torch"}, {["x"] = 4, ["meta"] = {["fields"] = {}, ["inventory"] = {}}, ["y"] = 5, ["param1"] = 204, ["z"] = 5, ["name"] = "default:fence_wood"}, {["x"] = 4, ["meta"] = {["fields"] = {}, ["inventory"] = {}}, ["param2"] = 1, ["y"] = 5, ["z"] = 6, ["name"] = "default:torch"}, {["x"] = 4, ["meta"] = {["fields"] = {}, ["inventory"] = {}}, ["y"] = 5, ["z"] = 9, ["name"] = "default:desert_stonebrick"}, {["x"] = 4, ["meta"] = {["fields"] = {}, ["inventory"] = {}}, ["y"] = 6, ["z"] = 0, ["name"] = "default:stonebrick"}, {["x"] = 4, ["meta"] = {["fields"] = {}, ["inventory"] = {}}, ["y"] = 6, ["param1"] = 187, ["z"] = 5, ["name"] = "default:fence_wood"}, {["x"] = 4, ["meta"] = {["fields"] = {}, ["inventory"] = {}}, ["y"] = 6, ["z"] = 9, ["name"] = "default:desert_stonebrick"}, {["x"] = 4, ["meta"] = {["fields"] = {}, ["inventory"] = {}}, ["y"] = 7, ["z"] = 0, ["name"] = "default:stonebrick"}, {["x"] = 4, ["meta"] = {["fields"] = {}, ["inventory"] = {}}, ["param2"] = 20, ["y"] = 7, ["param1"] = 187, ["z"] = 4, ["name"] = "stairs:stair_desert_stonebrick"}, {["x"] = 4, ["meta"] = {["fields"] = {}, ["inventory"] = {}}, ["y"] = 7, ["z"] = 5, ["name"] = "default:stonebrick"}, {["x"] = 4, ["meta"] = {["fields"] = {}, ["inventory"] = {}}, ["param2"] = 22, ["y"] = 7, ["param1"] = 187, ["z"] = 6, ["name"] = "stairs:stair_desert_stonebrick"}, {["x"] = 4, ["meta"] = {["fields"] = {}, ["inventory"] = {}}, ["param2"] = 23, ["y"] = 7, ["param1"] = 170, ["z"] = 7, ["name"] = "stairs:slab_stonebrick"}, {["x"] = 4, ["meta"] = {["fields"] = {}, ["inventory"] = {}}, ["y"] = 7, ["z"] = 8, ["name"] = "default:stonebrick"}, {["x"] = 4, ["meta"] = {["fields"] = {}, ["inventory"] = {}}, ["y"] = 7, ["z"] = 9, ["name"] = "default:desert_stonebrick"}, {["x"] = 4, ["meta"] = {["fields"] = {}, ["inventory"] = {}}, ["y"] = 8, ["param1"] = 111, ["z"] = 0, ["name"] = "default:desert_stonebrick"}, {["x"] = 4, ["meta"] = {["fields"] = {}, ["inventory"] = {}}, ["y"] = 8, ["z"] = 1, ["name"] = "default:desert_stonebrick"}, {["x"] = 4, ["meta"] = {["fields"] = {}, ["inventory"] = {}}, ["y"] = 8, ["z"] = 2, ["name"] = "default:desert_stonebrick"}, {["x"] = 4, ["meta"] = {["fields"] = {}, ["inventory"] = {}}, ["y"] = 8, ["z"] = 3, ["name"] = "default:desert_stonebrick"}, {["x"] = 4, ["meta"] = {["fields"] = {}, ["inventory"] = {}}, ["y"] = 8, ["z"] = 4, ["name"] = "default:desert_stonebrick"}, {["x"] = 4, ["meta"] = {["fields"] = {}, ["inventory"] = {}}, ["y"] = 8, ["z"] = 5, ["name"] = "default:desert_stonebrick"}, {["x"] = 4, ["meta"] = {["fields"] = {}, ["inventory"] = {}}, ["y"] = 8, ["z"] = 6, ["name"] = "default:desert_stonebrick"}, {["x"] = 4, ["meta"] = {["fields"] = {}, ["inventory"] = {}}, ["y"] = 8, ["z"] = 7, ["name"] = "default:desert_stonebrick"}, {["x"] = 4, ["meta"] = {["fields"] = {}, ["inventory"] = {}}, ["y"] = 8, ["z"] = 8, ["name"] = "default:desert_stonebrick"}, {["x"] = 4, ["meta"] = {["fields"] = {}, ["inventory"] = {}}, ["y"] = 8, ["z"] = 9, ["name"] = "default:desert_stonebrick"}, {["x"] = 5, ["meta"] = {["fields"] = {}, ["inventory"] = {}}, ["y"] = 0, ["z"] = 0, ["name"] = "default:desert_stonebrick"}, {["x"] = 5, ["meta"] = {["fields"] = {}, ["inventory"] = {}}, ["y"] = 0, ["z"] = 1, ["name"] = "default:desert_stonebrick"}, {["x"] = 5, ["meta"] = {["fields"] = {}, ["inventory"] = {}}, ["y"] = 0, ["z"] = 2, ["name"] = "default:desert_stonebrick"}, {["x"] = 5, ["meta"] = {["fields"] = {}, ["inventory"] = {}}, ["y"] = 0, ["z"] = 3, ["name"] = "default:stonebrick"}, {["x"] = 5, ["meta"] = {["fields"] = {}, ["inventory"] = {}}, ["y"] = 0, ["param1"] = 141, ["z"] = 4, ["name"] = "default:glass"}, {["x"] = 5, ["meta"] = {["fields"] = {}, ["inventory"] = {}}, ["y"] = 0, ["z"] = 5, ["name"] = "default:stonebrick"}, {["x"] = 5, ["meta"] = {["fields"] = {}, ["inventory"] = {}}, ["y"] = 0, ["z"] = 6, ["name"] = "default:desert_stonebrick"}, {["x"] = 5, ["meta"] = {["fields"] = {}, ["inventory"] = {}}, ["y"] = 0, ["z"] = 7, ["name"] = "default:desert_stonebrick"}, {["x"] = 5, ["meta"] = {["fields"] = {}, ["inventory"] = {}}, ["y"] = 0, ["z"] = 8, ["name"] = "default:desert_stonebrick"}, {["x"] = 5, ["meta"] = {["fields"] = {}, ["inventory"] = {}}, ["y"] = 0, ["z"] = 9, ["name"] = "default:desert_stonebrick"}, {["x"] = 5, ["meta"] = {["fields"] = {}, ["inventory"] = {}}, ["y"] = 1, ["z"] = 0, ["name"] = "default:stonebrick"}, {["x"] = 5, ["meta"] = {["fields"] = {}, ["inventory"] = {}}, ["y"] = 1, ["z"] = 1, ["name"] = "default:stonebrick"}, {["x"] = 5, ["meta"] = {["fields"] = {}, ["inventory"] = {}}, ["y"] = 1, ["param1"] = 187, ["z"] = 7, ["name"] = "stairs:slab_stonebrick"}, {["x"] = 5, ["meta"] = {["fields"] = {}, ["inventory"] = {}}, ["y"] = 1, ["z"] = 8, ["name"] = "default:stonebrick"}, {["x"] = 5, ["meta"] = {["fields"] = {}, ["inventory"] = {}}, ["y"] = 1, ["z"] = 9, ["name"] = "default:desert_stonebrick"}, {["x"] = 5, ["meta"] = {["fields"] = {}, ["inventory"] = {}}, ["y"] = 2, ["z"] = 0, ["name"] = "default:stonebrick"}, {["x"] = 5, ["meta"] = {["fields"] = {}, ["inventory"] = {}}, ["param2"] = 1, ["y"] = 2, ["z"] = 8, ["name"] = "default:torch"}, {["x"] = 5, ["meta"] = {["fields"] = {}, ["inventory"] = {}}, ["y"] = 2, ["z"] = 9, ["name"] = "default:desert_stonebrick"}, {["x"] = 5, ["meta"] = {["fields"] = {}, ["inventory"] = {}}, ["y"] = 3, ["z"] = 0, ["name"] = "default:stonebrick"}, {["x"] = 5, ["meta"] = {["fields"] = {}, ["inventory"] = {}}, ["y"] = 3, ["param1"] = 189, ["z"] = 9, ["name"] = "xpanes:bar_5"}, {["x"] = 5, ["meta"] = {["fields"] = {}, ["inventory"] = {}}, ["y"] = 4, ["param1"] = 141, ["z"] = 0, ["name"] = "xpanes:bar_5"}, {["x"] = 5, ["meta"] = {["fields"] = {}, ["inventory"] = {}}, ["y"] = 4, ["param1"] = 204, ["z"] = 4, ["name"] = "default:fence_wood"}, {["x"] = 5, ["meta"] = {["fields"] = {}, ["inventory"] = {}}, ["y"] = 4, ["param1"] = 204, ["z"] = 5, ["name"] = "default:fence_wood"}, {["x"] = 5, ["meta"] = {["fields"] = {}, ["inventory"] = {}}, ["y"] = 4, ["param1"] = 187, ["z"] = 6, ["name"] = "default:fence_wood"}, {["x"] = 5, ["meta"] = {["fields"] = {}, ["inventory"] = {}}, ["y"] = 4, ["z"] = 9, ["name"] = "default:desert_stonebrick"}, {["x"] = 5, ["meta"] = {["fields"] = {}, ["inventory"] = {}}, ["y"] = 5, ["z"] = 0, ["name"] = "default:stonebrick"}, {["x"] = 5, ["meta"] = {["fields"] = {}, ["inventory"] = {}}, ["param2"] = 1, ["y"] = 5, ["z"] = 4, ["name"] = "default:torch"}, {["x"] = 5, ["meta"] = {["fields"] = {}, ["inventory"] = {}}, ["param2"] = 1, ["y"] = 5, ["z"] = 5, ["name"] = "default:torch"}, {["x"] = 5, ["meta"] = {["fields"] = {}, ["inventory"] = {}}, ["y"] = 5, ["z"] = 9, ["name"] = "default:desert_stonebrick"}, {["x"] = 5, ["meta"] = {["fields"] = {}, ["inventory"] = {}}, ["y"] = 6, ["z"] = 0, ["name"] = "default:desert_stonebrick"}, {["x"] = 5, ["meta"] = {["fields"] = {}, ["inventory"] = {}}, ["y"] = 6, ["z"] = 9, ["name"] = "default:desert_stonebrick"}, {["x"] = 5, ["meta"] = {["fields"] = {}, ["inventory"] = {}}, ["y"] = 7, ["z"] = 0, ["name"] = "default:stonebrick"}, {["x"] = 5, ["meta"] = {["fields"] = {}, ["inventory"] = {}}, ["param2"] = 21, ["y"] = 7, ["param1"] = 187, ["z"] = 5, ["name"] = "stairs:stair_desert_stonebrick"}, {["x"] = 5, ["meta"] = {["fields"] = {}, ["inventory"] = {}}, ["param2"] = 23, ["y"] = 7, ["param1"] = 153, ["z"] = 7, ["name"] = "stairs:slab_stonebrick"}, {["x"] = 5, ["meta"] = {["fields"] = {}, ["inventory"] = {}}, ["y"] = 7, ["z"] = 8, ["name"] = "default:stonebrick"}, {["x"] = 5, ["meta"] = {["fields"] = {}, ["inventory"] = {}}, ["y"] = 7, ["z"] = 9, ["name"] = "default:desert_stonebrick"}, {["x"] = 5, ["meta"] = {["fields"] = {}, ["inventory"] = {}}, ["y"] = 8, ["param1"] = 111, ["z"] = 0, ["name"] = "default:desert_stonebrick"}, {["x"] = 5, ["meta"] = {["fields"] = {}, ["inventory"] = {}}, ["y"] = 8, ["z"] = 1, ["name"] = "default:desert_stonebrick"}, {["x"] = 5, ["meta"] = {["fields"] = {}, ["inventory"] = {}}, ["y"] = 8, ["z"] = 2, ["name"] = "default:desert_stonebrick"}, {["x"] = 5, ["meta"] = {["fields"] = {}, ["inventory"] = {}}, ["y"] = 8, ["z"] = 3, ["name"] = "default:desert_stonebrick"}, {["x"] = 5, ["meta"] = {["fields"] = {}, ["inventory"] = {}}, ["y"] = 8, ["z"] = 4, ["name"] = "default:desert_stonebrick"}, {["x"] = 5, ["meta"] = {["fields"] = {}, ["inventory"] = {}}, ["y"] = 8, ["z"] = 5, ["name"] = "default:desert_stonebrick"}, {["x"] = 5, ["meta"] = {["fields"] = {}, ["inventory"] = {}}, ["y"] = 8, ["z"] = 6, ["name"] = "default:desert_stonebrick"}, {["x"] = 5, ["meta"] = {["fields"] = {}, ["inventory"] = {}}, ["y"] = 8, ["z"] = 7, ["name"] = "default:desert_stonebrick"}, {["x"] = 5, ["meta"] = {["fields"] = {}, ["inventory"] = {}}, ["y"] = 8, ["z"] = 8, ["name"] = "default:desert_stonebrick"}, {["x"] = 5, ["meta"] = {["fields"] = {}, ["inventory"] = {}}, ["y"] = 8, ["z"] = 9, ["name"] = "default:desert_stonebrick"}, {["x"] = 6, ["meta"] = {["fields"] = {}, ["inventory"] = {}}, ["y"] = 0, ["z"] = 0, ["name"] = "default:desert_stonebrick"}, {["x"] = 6, ["meta"] = {["fields"] = {}, ["inventory"] = {}}, ["y"] = 0, ["z"] = 1, ["name"] = "default:desert_stonebrick"}, {["x"] = 6, ["meta"] = {["fields"] = {}, ["inventory"] = {}}, ["y"] = 0, ["z"] = 2, ["name"] = "default:desert_stonebrick"}, {["x"] = 6, ["meta"] = {["fields"] = {}, ["inventory"] = {}}, ["y"] = 0, ["z"] = 3, ["name"] = "default:desert_stonebrick"}, {["x"] = 6, ["meta"] = {["fields"] = {}, ["inventory"] = {}}, ["y"] = 0, ["z"] = 4, ["name"] = "default:desert_stonebrick"}, {["x"] = 6, ["meta"] = {["fields"] = {}, ["inventory"] = {}}, ["y"] = 0, ["z"] = 5, ["name"] = "default:desert_stonebrick"}, {["x"] = 6, ["meta"] = {["fields"] = {}, ["inventory"] = {}}, ["y"] = 0, ["z"] = 6, ["name"] = "default:desert_stonebrick"}, {["x"] = 6, ["meta"] = {["fields"] = {}, ["inventory"] = {}}, ["y"] = 0, ["z"] = 7, ["name"] = "default:desert_stonebrick"}, {["x"] = 6, ["meta"] = {["fields"] = {}, ["inventory"] = {}}, ["y"] = 0, ["z"] = 8, ["name"] = "default:desert_stonebrick"}, {["x"] = 6, ["meta"] = {["fields"] = {}, ["inventory"] = {}}, ["y"] = 0, ["z"] = 9, ["name"] = "default:desert_stonebrick"}, {["x"] = 6, ["meta"] = {["fields"] = {}, ["inventory"] = {}}, ["y"] = 1, ["z"] = 0, ["name"] = "default:stonebrick"}, {["x"] = 6, ["meta"] = {["fields"] = {}, ["inventory"] = {}}, ["y"] = 1, ["z"] = 1, ["name"] = "default:stonebrick"}, {["x"] = 6, ["meta"] = {["fields"] = {}, ["inventory"] = {}}, ["y"] = 1, ["z"] = 8, ["name"] = "default:stonebrick"}, {["x"] = 6, ["meta"] = {["fields"] = {}, ["inventory"] = {}}, ["y"] = 1, ["z"] = 9, ["name"] = "default:desert_stonebrick"}, {["x"] = 6, ["meta"] = {["fields"] = {}, ["inventory"] = {}}, ["y"] = 2, ["z"] = 0, ["name"] = "default:desert_stonebrick"}, {["x"] = 6, ["meta"] = {["fields"] = {}, ["inventory"] = {}}, ["y"] = 2, ["z"] = 9, ["name"] = "default:desert_stonebrick"}, {["x"] = 6, ["meta"] = {["fields"] = {}, ["inventory"] = {}}, ["y"] = 3, ["z"] = 0, ["name"] = "default:stonebrick"}, {["x"] = 6, ["meta"] = {["fields"] = {}, ["inventory"] = {}}, ["y"] = 3, ["z"] = 9, ["name"] = "default:desert_stonebrick"}, {["x"] = 6, ["meta"] = {["fields"] = {}, ["inventory"] = {}}, ["y"] = 4, ["z"] = 0, ["name"] = "default:stonebrick"}, {["x"] = 6, ["meta"] = {["fields"] = {}, ["inventory"] = {}}, ["y"] = 4, ["z"] = 9, ["name"] = "default:desert_stonebrick"}, {["x"] = 6, ["meta"] = {["fields"] = {}, ["inventory"] = {}}, ["y"] = 5, ["z"] = 0, ["name"] = "default:stonebrick"}, {["x"] = 6, ["meta"] = {["fields"] = {}, ["inventory"] = {}}, ["y"] = 5, ["z"] = 9, ["name"] = "default:desert_stonebrick"}, {["x"] = 6, ["meta"] = {["fields"] = {}, ["inventory"] = {}}, ["y"] = 6, ["param1"] = 127, ["z"] = 0, ["name"] = "default:desert_stonebrick"}, {["x"] = 6, ["meta"] = {["fields"] = {}, ["inventory"] = {}}, ["y"] = 6, ["z"] = 9, ["name"] = "default:desert_stonebrick"}, {["x"] = 6, ["meta"] = {["fields"] = {}, ["inventory"] = {}}, ["y"] = 7, ["z"] = 0, ["name"] = "default:stonebrick"}, {["x"] = 6, ["meta"] = {["fields"] = {}, ["inventory"] = {}}, ["param2"] = 23, ["y"] = 7, ["param1"] = 120, ["z"] = 1, ["name"] = "stairs:slab_stonebrick"}, {["x"] = 6, ["meta"] = {["fields"] = {}, ["inventory"] = {}}, ["param2"] = 23, ["y"] = 7, ["param1"] = 136, ["z"] = 2, ["name"] = "stairs:slab_stonebrick"}, {["x"] = 6, ["meta"] = {["fields"] = {}, ["inventory"] = {}}, ["param2"] = 23, ["y"] = 7, ["param1"] = 153, ["z"] = 3, ["name"] = "stairs:slab_stonebrick"}, {["x"] = 6, ["meta"] = {["fields"] = {}, ["inventory"] = {}}, ["param2"] = 23, ["y"] = 7, ["param1"] = 170, ["z"] = 4, ["name"] = "stairs:slab_stonebrick"}, {["x"] = 6, ["meta"] = {["fields"] = {}, ["inventory"] = {}}, ["param2"] = 23, ["y"] = 7, ["param1"] = 170, ["z"] = 5, ["name"] = "stairs:slab_stonebrick"}, {["x"] = 6, ["meta"] = {["fields"] = {}, ["inventory"] = {}}, ["param2"] = 23, ["y"] = 7, ["param1"] = 153, ["z"] = 6, ["name"] = "stairs:slab_stonebrick"}, {["x"] = 6, ["meta"] = {["fields"] = {}, ["inventory"] = {}}, ["param2"] = 23, ["y"] = 7, ["param1"] = 136, ["z"] = 7, ["name"] = "stairs:slab_stonebrick"}, {["x"] = 6, ["meta"] = {["fields"] = {}, ["inventory"] = {}}, ["y"] = 7, ["z"] = 8, ["name"] = "default:stonebrick"}, {["x"] = 6, ["meta"] = {["fields"] = {}, ["inventory"] = {}}, ["y"] = 7, ["z"] = 9, ["name"] = "default:desert_stonebrick"}, {["x"] = 6, ["meta"] = {["fields"] = {}, ["inventory"] = {}}, ["y"] = 8, ["param1"] = 95, ["z"] = 0, ["name"] = "default:desert_stonebrick"}, {["x"] = 6, ["meta"] = {["fields"] = {}, ["inventory"] = {}}, ["y"] = 8, ["z"] = 1, ["name"] = "default:desert_stonebrick"}, {["x"] = 6, ["meta"] = {["fields"] = {}, ["inventory"] = {}}, ["y"] = 8, ["z"] = 2, ["name"] = "default:desert_stonebrick"}, {["x"] = 6, ["meta"] = {["fields"] = {}, ["inventory"] = {}}, ["y"] = 8, ["z"] = 3, ["name"] = "default:desert_stonebrick"}, {["x"] = 6, ["meta"] = {["fields"] = {}, ["inventory"] = {}}, ["y"] = 8, ["z"] = 4, ["name"] = "default:desert_stonebrick"}, {["x"] = 6, ["meta"] = {["fields"] = {}, ["inventory"] = {}}, ["y"] = 8, ["z"] = 5, ["name"] = "default:desert_stonebrick"}, {["x"] = 6, ["meta"] = {["fields"] = {}, ["inventory"] = {}}, ["y"] = 8, ["z"] = 6, ["name"] = "default:desert_stonebrick"}, {["x"] = 6, ["meta"] = {["fields"] = {}, ["inventory"] = {}}, ["y"] = 8, ["z"] = 7, ["name"] = "default:desert_stonebrick"}, {["x"] = 6, ["meta"] = {["fields"] = {}, ["inventory"] = {}}, ["y"] = 8, ["z"] = 8, ["name"] = "default:desert_stonebrick"}, {["x"] = 6, ["meta"] = {["fields"] = {}, ["inventory"] = {}}, ["y"] = 8, ["z"] = 9, ["name"] = "default:desert_stonebrick"}, {["x"] = 7, ["meta"] = {["fields"] = {}, ["inventory"] = {}}, ["y"] = 0, ["z"] = 0, ["name"] = "default:desert_stonebrick"}, {["x"] = 7, ["meta"] = {["fields"] = {}, ["inventory"] = {}}, ["y"] = 0, ["z"] = 1, ["name"] = "default:desert_stonebrick"}, {["x"] = 7, ["meta"] = {["fields"] = {}, ["inventory"] = {}}, ["y"] = 0, ["z"] = 2, ["name"] = "default:desert_stonebrick"}, {["x"] = 7, ["meta"] = {["fields"] = {}, ["inventory"] = {}}, ["y"] = 0, ["z"] = 3, ["name"] = "default:desert_stonebrick"}, {["x"] = 7, ["meta"] = {["fields"] = {}, ["inventory"] = {}}, ["y"] = 0, ["z"] = 4, ["name"] = "default:desert_stonebrick"}, {["x"] = 7, ["meta"] = {["fields"] = {}, ["inventory"] = {}}, ["y"] = 0, ["z"] = 5, ["name"] = "default:desert_stonebrick"}, {["x"] = 7, ["meta"] = {["fields"] = {}, ["inventory"] = {}}, ["y"] = 0, ["z"] = 6, ["name"] = "default:desert_stonebrick"}, {["x"] = 7, ["meta"] = {["fields"] = {}, ["inventory"] = {}}, ["y"] = 0, ["z"] = 7, ["name"] = "default:desert_stonebrick"}, {["x"] = 7, ["meta"] = {["fields"] = {}, ["inventory"] = {}}, ["y"] = 0, ["z"] = 8, ["name"] = "default:desert_stonebrick"}, {["x"] = 7, ["meta"] = {["fields"] = {}, ["inventory"] = {}}, ["y"] = 0, ["z"] = 9, ["name"] = "default:desert_stonebrick"}, {["x"] = 7, ["meta"] = {["fields"] = {}, ["inventory"] = {}}, ["y"] = 1, ["z"] = 0, ["name"] = "default:stonebrick"}, {["x"] = 7, ["meta"] = {["fields"] = {}, ["inventory"] = {}}, ["y"] = 1, ["z"] = 1, ["name"] = "default:stonebrick"}, {["x"] = 7, ["meta"] = {["fields"] = {}, ["inventory"] = {}}, ["y"] = 1, ["z"] = 2, ["name"] = "default:stonebrick"}, {["x"] = 7, ["meta"] = {["fields"] = {}, ["inventory"] = {}}, ["y"] = 1, ["z"] = 3, ["name"] = "default:stonebrick"}, {["x"] = 7, ["meta"] = {["fields"] = {}, ["inventory"] = {}}, ["y"] = 1, ["z"] = 4, ["name"] = "default:stonebrick"}, {["x"] = 7, ["meta"] = {["fields"] = {}, ["inventory"] = {}}, ["y"] = 1, ["z"] = 5, ["name"] = "default:stonebrick"}, {["x"] = 7, ["meta"] = {["fields"] = {}, ["inventory"] = {}}, ["y"] = 1, ["z"] = 6, ["name"] = "default:stonebrick"}, {["x"] = 7, ["meta"] = {["fields"] = {}, ["inventory"] = {}}, ["y"] = 1, ["z"] = 7, ["name"] = "default:stonebrick"}, {["x"] = 7, ["meta"] = {["fields"] = {}, ["inventory"] = {}}, ["y"] = 1, ["z"] = 8, ["name"] = "default:stonebrick"}, {["x"] = 7, ["meta"] = {["fields"] = {}, ["inventory"] = {}}, ["y"] = 1, ["z"] = 9, ["name"] = "default:desert_stonebrick"}, {["x"] = 7, ["meta"] = {["fields"] = {}, ["inventory"] = {}}, ["y"] = 2, ["z"] = 0, ["name"] = "default:desert_stonebrick"}, {["x"] = 7, ["meta"] = {["fields"] = {}, ["inventory"] = {}}, ["y"] = 2, ["z"] = 9, ["name"] = "default:desert_stonebrick"}, {["x"] = 7, ["meta"] = {["fields"] = {}, ["inventory"] = {}}, ["y"] = 3, ["z"] = 0, ["name"] = "default:desert_stonebrick"}, {["x"] = 7, ["meta"] = {["fields"] = {}, ["inventory"] = {}}, ["y"] = 3, ["z"] = 9, ["name"] = "default:desert_stonebrick"}, {["x"] = 7, ["meta"] = {["fields"] = {}, ["inventory"] = {}}, ["y"] = 4, ["z"] = 0, ["name"] = "default:desert_stonebrick"}, {["x"] = 7, ["meta"] = {["fields"] = {}, ["inventory"] = {}}, ["y"] = 4, ["z"] = 9, ["name"] = "default:desert_stonebrick"}, {["x"] = 7, ["meta"] = {["fields"] = {}, ["inventory"] = {}}, ["y"] = 5, ["param1"] = 127, ["z"] = 0, ["name"] = "default:desert_stonebrick"}, {["x"] = 7, ["meta"] = {["fields"] = {}, ["inventory"] = {}}, ["y"] = 5, ["z"] = 9, ["name"] = "default:desert_stonebrick"}, {["x"] = 7, ["meta"] = {["fields"] = {}, ["inventory"] = {}}, ["y"] = 6, ["param1"] = 111, ["z"] = 0, ["name"] = "default:desert_stonebrick"}, {["x"] = 7, ["meta"] = {["fields"] = {}, ["inventory"] = {}}, ["y"] = 6, ["z"] = 9, ["name"] = "default:desert_stonebrick"}, {["x"] = 7, ["meta"] = {["fields"] = {}, ["inventory"] = {}}, ["y"] = 7, ["z"] = 0, ["name"] = "default:stonebrick"}, {["x"] = 7, ["meta"] = {["fields"] = {}, ["inventory"] = {}}, ["y"] = 7, ["z"] = 1, ["name"] = "default:stonebrick"}, {["x"] = 7, ["meta"] = {["fields"] = {}, ["inventory"] = {}}, ["y"] = 7, ["z"] = 2, ["name"] = "default:stonebrick"}, {["x"] = 7, ["meta"] = {["fields"] = {}, ["inventory"] = {}}, ["y"] = 7, ["z"] = 3, ["name"] = "default:stonebrick"}, {["x"] = 7, ["meta"] = {["fields"] = {}, ["inventory"] = {}}, ["y"] = 7, ["z"] = 4, ["name"] = "default:stonebrick"}, {["x"] = 7, ["meta"] = {["fields"] = {}, ["inventory"] = {}}, ["y"] = 7, ["z"] = 5, ["name"] = "default:stonebrick"}, {["x"] = 7, ["meta"] = {["fields"] = {}, ["inventory"] = {}}, ["y"] = 7, ["z"] = 6, ["name"] = "default:stonebrick"}, {["x"] = 7, ["meta"] = {["fields"] = {}, ["inventory"] = {}}, ["y"] = 7, ["z"] = 7, ["name"] = "default:stonebrick"}, {["x"] = 7, ["meta"] = {["fields"] = {}, ["inventory"] = {}}, ["y"] = 7, ["z"] = 8, ["name"] = "default:stonebrick"}, {["x"] = 7, ["meta"] = {["fields"] = {}, ["inventory"] = {}}, ["y"] = 7, ["z"] = 9, ["name"] = "default:desert_stonebrick"}, {["x"] = 7, ["meta"] = {["fields"] = {}, ["inventory"] = {}}, ["y"] = 8, ["param1"] = 79, ["z"] = 0, ["name"] = "default:desert_stonebrick"}, {["x"] = 7, ["meta"] = {["fields"] = {}, ["inventory"] = {}}, ["y"] = 8, ["z"] = 1, ["name"] = "default:desert_stonebrick"}, {["x"] = 7, ["meta"] = {["fields"] = {}, ["inventory"] = {}}, ["y"] = 8, ["z"] = 2, ["name"] = "default:desert_stonebrick"}, {["x"] = 7, ["meta"] = {["fields"] = {}, ["inventory"] = {}}, ["y"] = 8, ["z"] = 3, ["name"] = "default:desert_stonebrick"}, {["x"] = 7, ["meta"] = {["fields"] = {}, ["inventory"] = {}}, ["y"] = 8, ["z"] = 4, ["name"] = "default:desert_stonebrick"}, {["x"] = 7, ["meta"] = {["fields"] = {}, ["inventory"] = {}}, ["y"] = 8, ["z"] = 5, ["name"] = "default:desert_stonebrick"}, {["x"] = 7, ["meta"] = {["fields"] = {}, ["inventory"] = {}}, ["y"] = 8, ["z"] = 6, ["name"] = "default:desert_stonebrick"}, {["x"] = 7, ["meta"] = {["fields"] = {}, ["inventory"] = {}}, ["y"] = 8, ["z"] = 7, ["name"] = "default:desert_stonebrick"}, {["x"] = 7, ["meta"] = {["fields"] = {}, ["inventory"] = {}}, ["y"] = 8, ["z"] = 8, ["name"] = "default:desert_stonebrick"}, {["x"] = 7, ["meta"] = {["fields"] = {}, ["inventory"] = {}}, ["y"] = 8, ["z"] = 9, ["name"] = "default:desert_stonebrick"}, {["x"] = 8, ["meta"] = {["fields"] = {}, ["inventory"] = {}}, ["y"] = 0, ["z"] = 0, ["name"] = "default:desert_stonebrick"}, {["x"] = 8, ["meta"] = {["fields"] = {}, ["inventory"] = {}}, ["y"] = 0, ["z"] = 1, ["name"] = "default:desert_stonebrick"}, {["x"] = 8, ["meta"] = {["fields"] = {}, ["inventory"] = {}}, ["y"] = 0, ["z"] = 2, ["name"] = "default:desert_stonebrick"}, {["x"] = 8, ["meta"] = {["fields"] = {}, ["inventory"] = {}}, ["y"] = 0, ["z"] = 3, ["name"] = "default:desert_stonebrick"}, {["x"] = 8, ["meta"] = {["fields"] = {}, ["inventory"] = {}}, ["y"] = 0, ["z"] = 4, ["name"] = "default:desert_stonebrick"}, {["x"] = 8, ["meta"] = {["fields"] = {}, ["inventory"] = {}}, ["y"] = 0, ["z"] = 5, ["name"] = "default:desert_stonebrick"}, {["x"] = 8, ["meta"] = {["fields"] = {}, ["inventory"] = {}}, ["y"] = 0, ["z"] = 6, ["name"] = "default:desert_stonebrick"}, {["x"] = 8, ["meta"] = {["fields"] = {}, ["inventory"] = {}}, ["y"] = 0, ["z"] = 7, ["name"] = "default:desert_stonebrick"}, {["x"] = 8, ["meta"] = {["fields"] = {}, ["inventory"] = {}}, ["y"] = 0, ["z"] = 8, ["name"] = "default:desert_stonebrick"}, {["x"] = 8, ["meta"] = {["fields"] = {}, ["inventory"] = {}}, ["y"] = 0, ["z"] = 9, ["name"] = "default:desert_stonebrick"}, {["x"] = 8, ["meta"] = {["fields"] = {}, ["inventory"] = {}}, ["y"] = 1, ["z"] = 0, ["name"] = "default:stonebrick"}, {["x"] = 8, ["meta"] = {["fields"] = {}, ["inventory"] = {}}, ["y"] = 1, ["z"] = 1, ["name"] = "default:desert_stonebrick"}, {["x"] = 8, ["meta"] = {["fields"] = {}, ["inventory"] = {}}, ["y"] = 1, ["z"] = 2, ["name"] = "default:desert_stonebrick"}, {["x"] = 8, ["meta"] = {["fields"] = {}, ["inventory"] = {}}, ["y"] = 1, ["z"] = 3, ["name"] = "default:desert_stonebrick"}, {["x"] = 8, ["meta"] = {["fields"] = {}, ["inventory"] = {}}, ["y"] = 1, ["z"] = 4, ["name"] = "default:desert_stonebrick"}, {["x"] = 8, ["meta"] = {["fields"] = {}, ["inventory"] = {}}, ["y"] = 1, ["z"] = 5, ["name"] = "default:desert_stonebrick"}, {["x"] = 8, ["meta"] = {["fields"] = {}, ["inventory"] = {}}, ["y"] = 1, ["z"] = 6, ["name"] = "default:desert_stonebrick"}, {["x"] = 8, ["meta"] = {["fields"] = {}, ["inventory"] = {}}, ["y"] = 1, ["z"] = 7, ["name"] = "default:desert_stonebrick"}, {["x"] = 8, ["meta"] = {["fields"] = {}, ["inventory"] = {}}, ["y"] = 1, ["z"] = 8, ["name"] = "default:desert_stonebrick"}, {["x"] = 8, ["meta"] = {["fields"] = {}, ["inventory"] = {}}, ["y"] = 1, ["z"] = 9, ["name"] = "default:desert_stonebrick"}, {["x"] = 8, ["meta"] = {["fields"] = {}, ["inventory"] = {}}, ["y"] = 2, ["z"] = 0, ["name"] = "default:desert_stonebrick"}, {["x"] = 8, ["meta"] = {["fields"] = {}, ["inventory"] = {}}, ["y"] = 2, ["z"] = 1, ["name"] = "default:desert_stonebrick"}, {["x"] = 8, ["meta"] = {["fields"] = {}, ["inventory"] = {}}, ["y"] = 2, ["z"] = 2, ["name"] = "default:desert_stonebrick"}, {["x"] = 8, ["meta"] = {["fields"] = {}, ["inventory"] = {}}, ["y"] = 2, ["z"] = 3, ["name"] = "default:desert_stonebrick"}, {["x"] = 8, ["meta"] = {["fields"] = {}, ["inventory"] = {}}, ["y"] = 2, ["z"] = 4, ["name"] = "default:desert_stonebrick"}, {["x"] = 8, ["meta"] = {["fields"] = {}, ["inventory"] = {}}, ["y"] = 2, ["z"] = 5, ["name"] = "default:desert_stonebrick"}, {["x"] = 8, ["meta"] = {["fields"] = {}, ["inventory"] = {}}, ["y"] = 2, ["z"] = 6, ["name"] = "default:desert_stonebrick"}, {["x"] = 8, ["meta"] = {["fields"] = {}, ["inventory"] = {}}, ["y"] = 2, ["z"] = 7, ["name"] = "default:desert_stonebrick"}, {["x"] = 8, ["meta"] = {["fields"] = {}, ["inventory"] = {}}, ["y"] = 2, ["z"] = 8, ["name"] = "default:desert_stonebrick"}, {["x"] = 8, ["meta"] = {["fields"] = {}, ["inventory"] = {}}, ["y"] = 2, ["z"] = 9, ["name"] = "default:desert_stonebrick"}, {["x"] = 8, ["meta"] = {["fields"] = {}, ["inventory"] = {}}, ["y"] = 3, ["z"] = 0, ["name"] = "default:desert_stonebrick"}, {["x"] = 8, ["meta"] = {["fields"] = {}, ["inventory"] = {}}, ["y"] = 3, ["z"] = 1, ["name"] = "default:desert_stonebrick"}, {["x"] = 8, ["meta"] = {["fields"] = {}, ["inventory"] = {}}, ["y"] = 3, ["z"] = 2, ["name"] = "default:desert_stonebrick"}, {["x"] = 8, ["meta"] = {["fields"] = {}, ["inventory"] = {}}, ["y"] = 3, ["z"] = 3, ["name"] = "default:desert_stonebrick"}, {["x"] = 8, ["meta"] = {["fields"] = {}, ["inventory"] = {}}, ["y"] = 3, ["param1"] = 141, ["z"] = 4, ["name"] = "xpanes:bar_10"}, {["x"] = 8, ["meta"] = {["fields"] = {}, ["inventory"] = {}}, ["y"] = 3, ["param1"] = 141, ["z"] = 5, ["name"] = "xpanes:bar_10"}, {["x"] = 8, ["meta"] = {["fields"] = {}, ["inventory"] = {}}, ["y"] = 3, ["param1"] = 125, ["z"] = 6, ["name"] = "xpanes:bar_10"}, {["x"] = 8, ["meta"] = {["fields"] = {}, ["inventory"] = {}}, ["y"] = 3, ["z"] = 7, ["name"] = "default:desert_stonebrick"}, {["x"] = 8, ["meta"] = {["fields"] = {}, ["inventory"] = {}}, ["y"] = 3, ["z"] = 8, ["name"] = "default:desert_stonebrick"}, {["x"] = 8, ["meta"] = {["fields"] = {}, ["inventory"] = {}}, ["y"] = 3, ["z"] = 9, ["name"] = "default:desert_stonebrick"}, {["x"] = 8, ["meta"] = {["fields"] = {}, ["inventory"] = {}}, ["y"] = 4, ["z"] = 0, ["name"] = "default:desert_stonebrick"}, {["x"] = 8, ["meta"] = {["fields"] = {}, ["inventory"] = {}}, ["y"] = 4, ["z"] = 1, ["name"] = "default:desert_stonebrick"}, {["x"] = 8, ["meta"] = {["fields"] = {}, ["inventory"] = {}}, ["y"] = 4, ["z"] = 2, ["name"] = "default:desert_stonebrick"}, {["x"] = 8, ["meta"] = {["fields"] = {}, ["inventory"] = {}}, ["y"] = 4, ["z"] = 3, ["name"] = "default:desert_stonebrick"}, {["x"] = 8, ["meta"] = {["fields"] = {}, ["inventory"] = {}}, ["y"] = 4, ["z"] = 4, ["name"] = "default:desert_stonebrick"}, {["x"] = 8, ["meta"] = {["fields"] = {}, ["inventory"] = {}}, ["y"] = 4, ["z"] = 5, ["name"] = "default:desert_stonebrick"}, {["x"] = 8, ["meta"] = {["fields"] = {}, ["inventory"] = {}}, ["y"] = 4, ["z"] = 6, ["name"] = "default:desert_stonebrick"}, {["x"] = 8, ["meta"] = {["fields"] = {}, ["inventory"] = {}}, ["y"] = 4, ["z"] = 7, ["name"] = "default:desert_stonebrick"}, {["x"] = 8, ["meta"] = {["fields"] = {}, ["inventory"] = {}}, ["y"] = 4, ["z"] = 8, ["name"] = "default:desert_stonebrick"}, {["x"] = 8, ["meta"] = {["fields"] = {}, ["inventory"] = {}}, ["y"] = 4, ["z"] = 9, ["name"] = "default:desert_stonebrick"}, {["x"] = 8, ["meta"] = {["fields"] = {}, ["inventory"] = {}}, ["y"] = 5, ["param1"] = 111, ["z"] = 0, ["name"] = "default:desert_stonebrick"}, {["x"] = 8, ["meta"] = {["fields"] = {}, ["inventory"] = {}}, ["y"] = 5, ["z"] = 1, ["name"] = "default:desert_stonebrick"}, {["x"] = 8, ["meta"] = {["fields"] = {}, ["inventory"] = {}}, ["y"] = 5, ["z"] = 2, ["name"] = "default:desert_stonebrick"}, {["x"] = 8, ["meta"] = {["fields"] = {}, ["inventory"] = {}}, ["y"] = 5, ["z"] = 3, ["name"] = "default:desert_stonebrick"}, {["x"] = 8, ["meta"] = {["fields"] = {}, ["inventory"] = {}}, ["y"] = 5, ["z"] = 4, ["name"] = "default:desert_stonebrick"}, {["x"] = 8, ["meta"] = {["fields"] = {}, ["inventory"] = {}}, ["y"] = 5, ["z"] = 5, ["name"] = "default:desert_stonebrick"}, {["x"] = 8, ["meta"] = {["fields"] = {}, ["inventory"] = {}}, ["y"] = 5, ["z"] = 6, ["name"] = "default:desert_stonebrick"}, {["x"] = 8, ["meta"] = {["fields"] = {}, ["inventory"] = {}}, ["y"] = 5, ["z"] = 7, ["name"] = "default:desert_stonebrick"}, {["x"] = 8, ["meta"] = {["fields"] = {}, ["inventory"] = {}}, ["y"] = 5, ["z"] = 8, ["name"] = "default:desert_stonebrick"}, {["x"] = 8, ["meta"] = {["fields"] = {}, ["inventory"] = {}}, ["y"] = 5, ["z"] = 9, ["name"] = "default:desert_stonebrick"}, {["x"] = 8, ["meta"] = {["fields"] = {}, ["inventory"] = {}}, ["y"] = 6, ["param1"] = 95, ["z"] = 0, ["name"] = "default:desert_stonebrick"}, {["x"] = 8, ["meta"] = {["fields"] = {}, ["inventory"] = {}}, ["y"] = 6, ["z"] = 1, ["name"] = "default:desert_stonebrick"}, {["x"] = 8, ["meta"] = {["fields"] = {}, ["inventory"] = {}}, ["y"] = 6, ["z"] = 2, ["name"] = "default:desert_stonebrick"}, {["x"] = 8, ["meta"] = {["fields"] = {}, ["inventory"] = {}}, ["y"] = 6, ["z"] = 3, ["name"] = "default:desert_stonebrick"}, {["x"] = 8, ["meta"] = {["fields"] = {}, ["inventory"] = {}}, ["y"] = 6, ["z"] = 4, ["name"] = "default:desert_stonebrick"}, {["x"] = 8, ["meta"] = {["fields"] = {}, ["inventory"] = {}}, ["y"] = 6, ["z"] = 5, ["name"] = "default:desert_stonebrick"}, {["x"] = 8, ["meta"] = {["fields"] = {}, ["inventory"] = {}}, ["y"] = 6, ["z"] = 6, ["name"] = "default:desert_stonebrick"}, {["x"] = 8, ["meta"] = {["fields"] = {}, ["inventory"] = {}}, ["y"] = 6, ["z"] = 7, ["name"] = "default:desert_stonebrick"}, {["x"] = 8, ["meta"] = {["fields"] = {}, ["inventory"] = {}}, ["y"] = 6, ["z"] = 8, ["name"] = "default:desert_stonebrick"}, {["x"] = 8, ["meta"] = {["fields"] = {}, ["inventory"] = {}}, ["y"] = 6, ["z"] = 9, ["name"] = "default:desert_stonebrick"}, {["x"] = 8, ["meta"] = {["fields"] = {}, ["inventory"] = {}}, ["y"] = 7, ["param1"] = 79, ["z"] = 0, ["name"] = "default:desert_stonebrick"}, {["x"] = 8, ["meta"] = {["fields"] = {}, ["inventory"] = {}}, ["y"] = 7, ["z"] = 1, ["name"] = "default:desert_stonebrick"}, {["x"] = 8, ["meta"] = {["fields"] = {}, ["inventory"] = {}}, ["y"] = 7, ["z"] = 2, ["name"] = "default:desert_stonebrick"}, {["x"] = 8, ["meta"] = {["fields"] = {}, ["inventory"] = {}}, ["y"] = 7, ["z"] = 3, ["name"] = "default:desert_stonebrick"}, {["x"] = 8, ["meta"] = {["fields"] = {}, ["inventory"] = {}}, ["y"] = 7, ["z"] = 4, ["name"] = "default:desert_stonebrick"}, {["x"] = 8, ["meta"] = {["fields"] = {}, ["inventory"] = {}}, ["y"] = 7, ["z"] = 5, ["name"] = "default:desert_stonebrick"}, {["x"] = 8, ["meta"] = {["fields"] = {}, ["inventory"] = {}}, ["y"] = 7, ["z"] = 6, ["name"] = "default:desert_stonebrick"}, {["x"] = 8, ["meta"] = {["fields"] = {}, ["inventory"] = {}}, ["y"] = 7, ["z"] = 7, ["name"] = "default:desert_stonebrick"}, {["x"] = 8, ["meta"] = {["fields"] = {}, ["inventory"] = {}}, ["y"] = 7, ["z"] = 8, ["name"] = "default:desert_stonebrick"}, {["x"] = 8, ["meta"] = {["fields"] = {}, ["inventory"] = {}}, ["y"] = 7, ["z"] = 9, ["name"] = "default:desert_stonebrick"}, {["x"] = 8, ["meta"] = {["fields"] = {}, ["inventory"] = {}}, ["y"] = 8, ["param1"] = 63, ["z"] = 0, ["name"] = "default:desert_stonebrick"}, {["x"] = 8, ["meta"] = {["fields"] = {}, ["inventory"] = {}}, ["y"] = 8, ["z"] = 1, ["name"] = "default:desert_stonebrick"}, {["x"] = 8, ["meta"] = {["fields"] = {}, ["inventory"] = {}}, ["y"] = 8, ["z"] = 2, ["name"] = "default:desert_stonebrick"}, {["x"] = 8, ["meta"] = {["fields"] = {}, ["inventory"] = {}}, ["y"] = 8, ["z"] = 3, ["name"] = "default:desert_stonebrick"}, {["x"] = 8, ["meta"] = {["fields"] = {}, ["inventory"] = {}}, ["y"] = 8, ["z"] = 4, ["name"] = "default:desert_stonebrick"}, {["x"] = 8, ["meta"] = {["fields"] = {}, ["inventory"] = {}}, ["y"] = 8, ["z"] = 5, ["name"] = "default:desert_stonebrick"}, {["x"] = 8, ["meta"] = {["fields"] = {}, ["inventory"] = {}}, ["y"] = 8, ["z"] = 6, ["name"] = "default:desert_stonebrick"}, {["x"] = 8, ["meta"] = {["fields"] = {}, ["inventory"] = {}}, ["y"] = 8, ["z"] = 7, ["name"] = "default:desert_stonebrick"}, {["x"] = 8, ["meta"] = {["fields"] = {}, ["inventory"] = {}}, ["y"] = 8, ["z"] = 8, ["name"] = "default:desert_stonebrick"}, {["x"] = 8, ["meta"] = {["fields"] = {}, ["inventory"] = {}}, ["y"] = 8, ["z"] = 9, ["name"] = "default:desert_stonebrick"}}